2025-10-12 01:35:42,749 [[31mERROR[0m[0m[0m] hyperx.bin.cli.logger.setenv (setenv.py:34) :: Setup failed: 'LOG_DIR'
Traceback (most recent call last):
  File "/home/faron/Public/gits/hyperx-htmx/hyperx/bin/cli/logger/setenv.py", line 13, in main
    BASE_LOG = Path(os.environ["LOG_DIR"])
                    ~~~~~~~~~~^^^^^^^^^^^
  File "<frozen os>", line 714, in __getitem__
KeyError: 'LOG_DIR'
2025-10-12 01:39:54,349 [[33mWARNING[0m[0m[0m] hyperx.bin.cli.logger.setenv (setenv.py:28) :: Creating missing file: /home/faron/Public/gits/hyperx-htmx/hyperx/bin/cli/logs/_reports/record.log
2025-10-12 01:39:54,349 [[33mWARNING[0m[0m[0m] hyperx.bin.cli.logger.setenv (setenv.py:28) :: Creating missing file: /home/faron/Public/gits/hyperx-htmx/hyperx/bin/cli/logs/_reports/monitor.log
2025-10-12 01:39:54,350 [[33mWARNING[0m[0m[0m] hyperx.bin.cli.logger.setenv (setenv.py:28) :: Creating missing file: /home/faron/Public/gits/hyperx-htmx/hyperx/bin/cli/logs/_reports/worker.log
2025-10-12 01:39:54,350 [[33mWARNING[0m[0m[0m] hyperx.bin.cli.logger.setenv (setenv.py:28) :: Creating missing file: /home/faron/Public/gits/hyperx-htmx/hyperx/bin/cli/logs/_reports/registrar.log
2025-10-12 01:39:54,350 [[33mWARNING[0m[0m[0m] hyperx.bin.cli.logger.setenv (setenv.py:28) :: Creating missing file: /home/faron/Public/gits/hyperx-htmx/hyperx/bin/cli/logs/_reports/attendance.log
2025-10-12 01:39:54,350 [[32mINFO[0m[0m[0m] hyperx.bin.cli.logger.setenv (setenv.py:33) :: Environment verification complete.
